Workbook

Sheet fx deals outs reworked
A1: Header1 | B1: Trade Type | C1: Deal Date | D1: Value Date | E1: Counterparty | F1: External Counterparty | G1: Direction | H1: CCY 1 Amount | I1: CCY 1 | J1: CCY 2 Amount | K1: CCY 2 | L1: Exchange Rate | M1: Book | N1: Dealer | O1: Status | P1: TPL | Q1: Cash | R1: Val
A2: 8815281 | B2: FX Fwd | C2: 44064.456 | D2: 44102 | E2: IRELAND BLYTH LIMITED | F2: IRELAND BLYTH LIMITED | G2: Sell | H2: -137046.2 | I2: USD | J2: 5457179.7 | K2: MUR | L2: 39.82 | M2: MR_ON SandT CIB_FX | N2: G01884883 | O2: BO Confirmed | P2: -10595.465 | Q2: 0 | R2: -10595.465
A3: 8815264 | B3: FX Fwd | C3: 44064.454 | D3: 44089 | E3: IRELAND BLYTH LIMITED | F3: IRELAND BLYTH LIMITED | G3: Sell | H3: -402672.19 | I3: USD | J3: 16026353 | K3: MUR | L3: 39.8 | M3: MR_ON SandT CIB_FX | N3: G01884883 | O3: BO Confirmed | P3: -32450.035 | Q3: 0 | R3: -32450.035
A4: 8815243 | B4: FX Fwd | C4: 44064.451 | D4: 44082 | E4: IRELAND BLYTH LIMITED | F4: IRELAND BLYTH LIMITED | G4: Sell | H4: -154721.03 | I4: USD | J4: 6157123.4 | K4: MUR | L4: 39.795 | M4: MR_ON SandT CIB_FX | N4: G01884883 | O4: BO Confirmed | P4: -11814.113 | Q4: 0 | R4: -11814.113
A5: 8815210 | B5: FX Fwd | C5: 44064.448 | D5: 44098 | E5: IRELAND BLYTH LIMITED | F5: IRELAND BLYTH LIMITED | G5: Sell | H5: -108530 | I5: EUR | J5: 5106336.5 | K5: MUR | L5: 47.05 | M5: MR_ON SandT CIB_FX | N5: G01884883 | O5: BO Confirmed | P5: 2569.2136 | Q5: 0 | R5: 2569.2136
A6: 8815172 | B6: FX Fwd | C6: 44064.445 | D6: 44075 | E6: IRELAND BLYTH LIMITED | F6: IRELAND BLYTH LIMITED | G6: Sell | H6: -416268.72 | I6: EUR | J6: 19570874 | K6: MUR | L6: 47.015 | M6: MR_ON SandT CIB_FX | N6: G01884883 | O6: BO-BO Confirmed | P6: 19367.681 | Q6: 0 | R6: 19367.681
A7: 8802697 | B7: FX Fwd | C7: 44062.35 | D7: 44186 | E7: MAURITIUS SUGAR SYNDICATE | F7: MAURITIUS SUGAR SYNDICATE | G7: Buy | H7: 500000 | I7: EUR | J7: -23750000 | K7: MUR | L7: 47.5 | M7: MR_ON SandT CIB_FX | N7: H10042101 | O7: BO-BO Confirmed | P7: -123786.83 | Q7: 0 | R7: -123786.83
A8: 8802001 | B8: FX Fwd | C8: 44062.268 | D8: 44085 | E8: MAURITIUS SUGAR SYNDICATE | F8: MAURITIUS SUGAR SYNDICATE | G8: Buy | H8: 500000 | I8: EUR | J8: -597050 | K8: USD | L8: 1.1941 | M8: MR_ON SandT CIB_FX | N8: G01201900 | O8: BO-BO Confirmed | P8: -310380.9 | Q8: 0 | R8: -310380.9
A9: 8797817 | B9: FX Fwd | C9: 44061.297 | D9: 44266 | E9: LAFARGE | F9: LAFARGE | G9: Sell | H9: -720000 | I9: USD | J9: 28656000 | K9: MUR | L9: 39.8 | M9: MR_ON SandT CIB_FX | N9: H10042101 | O9: BO-BO Confirmed | P9: -248546.2 | Q9: 0 | R9: -248546.2
A10: 8797463 | B10: FX Fwd | C10: 44061.208 | D10: 44085 | E10: MAURITIUS SUGAR SYNDICATE | F10: MAURITIUS SUGAR SYNDICATE | G10: Buy | H10: 500000 | I10: EUR | J10: -594600 | K10: USD | L10: 1.1892 | M10: MR_ON SandT CIB_FX | N10: H10042101 | O10: BO-BO Confirmed | P10: -212764.08 | Q10: 0 | R10: -212764.08
A11: 8794326 | B11: FX Fwd | C11: 44060.431 | D11: 44238 | E11: LAFARGE | F11: LAFARGE | G11: Sell | H11: -720000 | I11: USD | J11: 28656000 | K11: MUR | L11: 39.8 | M11: MR_ON SandT CIB_FX | N11: H10042101 | O11: BO-BO Confirmed | P11: -213813.46 | Q11: 0 | R11: -213813.46
A12: 8794298 | B12: FX Fwd | C12: 44060.427 | D12: 44279 | E12: DUCRAY LENOIR LIMITED | F12: DUCRAY LENOIR LIMITED | G12: Sell | H12: -608279 | I12: USD | J12: 24391988 | K12: MUR | L12: 40.1 | M12: MR_ON SandT CIB_FX | N12: G01884883 | O12: BO-BO Confirmed | P12: -41834.009 | Q12: 0 | R12: -41834.009
A13: 8792768 | B13: FX Fwd | C13: 44060.288 | D13: 44208 | E13: LAFARGE | F13: LAFARGE | G13: Sell | H13: -720000 | I13: USD | J13: 28656000 | K13: MUR | L13: 39.8 | M13: MR_ON SandT CIB_FX | N13: H10042101 | O13: BO-BO Confirmed | P13: -174952.14 | Q13: 0 | R13: -174952.14
... A66: 8114992 | B66: FX Fwd | C66: 43896.243 | D66: 44104 | E66: MAURITIUS SUGAR SYNDICATE | F66: MAURITIUS SUGAR SYNDICATE | G66: Buy | H66: 1000000 | I66: EUR | J66: -42150000 | K66: MUR | L66: 42.15 | M66: MR_ON SandT CIB_FX | N66: A94100698 | O66: BO-BO Confirmed | P66: 4883471.8 | Q66: 0 | R66: 4883471.8
A67: 8080331 | B67: FX Fwd | C67: 43892.367 | D67: 44104 | E67: ABSA BANK | G67: Buy | H67: 735000 | I67: EUR | J67: -30847950 | K67: MUR | L67: 41.97 | M67: MR_ON SandT FXMarkets | N67: G44529946 | O67: BO-BO Confirmed | P67: 3721449.4 | Q67: 0 | R67: 3721449.4
A68: 8079226 | B68: FX Fwd | C68: 43892.293 | D68: 44111 | E68: AZUR FINANCIAL SERVICES LTD | F68: AZUR FINANCIAL SERVICES LTD | G68: Sell | H68: -500000 | I68: USD | J68: 18775000 | K68: MUR | L68: 37.55 | M68: MR_ON SandT CIB_FX | N68: A94100042 | O68: BO-BO Confirmed | P68: -1177247.7 | Q68: 0 | R68: -1177247.7
A69: 8079058 | B69: FX Fwd | C69: 43892.272 | D69: 44111 | E69: AZUR FINANCIAL SERVICES LTD | F69: AZUR FINANCIAL SERVICES LTD | G69: Sell | H69: -500000 | I69: USD | J69: 18775000 | K69: MUR | L69: 37.55 | M69: MR_ON SandT CIB_FX | N69: A94100042 | O69: BO-BO Confirmed | P69: -1177247.7 | Q69: 0 | R69: -1177247.7
A70: 8072214 | B70: FX Fwd | C70: 43889.337 | D70: 44110 | E70: AZUR FINANCIAL SERVICES LTD | F70: AZUR FINANCIAL SERVICES LTD | G70: Sell | H70: -500000 | I70: USD | J70: 18805000 | K70: MUR | L70: 37.61 | M70: MR_ON SandT CIB_FX | N70: A94100698 | O70: BO-BO Confirmed | P70: -1146721.7 | Q70: 0 | R70: -1146721.7
A71: 8062038 | B71: FX Fwd | C71: 43888.402 | D71: 44104 | E71: AZUR FINANCIAL SERVICES LTD | F71: AZUR FINANCIAL SERVICES LTD | G71: Sell | H71: -500000 | I71: USD | J71: 18865000 | K71: MUR | L71: 37.73 | M71: MR_ON SandT CIB_FX | N71: A94100698 | O71: BO-BO Confirmed | P71: -1083316.6 | Q71: 0 | R71: -1083316.6
A72: 8061545 | B72: FX Fwd | C72: 43888.368 | D72: 44109 | E72: AZUR FINANCIAL SERVICES LTD | F72: AZUR FINANCIAL SERVICES LTD | G72: Sell | H72: -500000 | I72: USD | J72: 18865000 | K72: MUR | L72: 37.73 | M72: MR_ON SandT CIB_FX | N72: A94100698 | O72: BO-BO Confirmed | P72: -1086244.3 | Q72: 0 | R72: -1086244.3
A73: 8055715 | B73: FX Fwd | C73: 43887.466 | D73: 44109 | E73: AZUR FINANCIAL SERVICES LTD | F73: AZUR FINANCIAL SERVICES LTD | G73: Sell | H73: -500000 | I73: USD | J73: 18885000 | K73: MUR | L73: 37.77 | M73: MR_ON SandT CIB_FX | N73: G01884883 | O73: BO-BO Confirmed | P73: -1066278.8 | Q73: 0 | R73: -1066278.8
A74: 8053975 | B74: FX Fwd | C74: 43887.359 | D74: 44109 | E74: AZUR FINANCIAL SERVICES LTD | F74: AZUR FINANCIAL SERVICES LTD | G74: Sell | H74: -1000000 | I74: USD | J74: 37775000 | K74: MUR | L74: 37.775 | M74: MR_ON SandT CIB_FX | N74: A94100698 | O74: BO-BO Confirmed | P74: -2127566.1 | Q74: 0 | R74: -2127566.1
A75: 8034484 | B75: FX Fwd | C75: 43881.407 | D75: 44104 | E75: ABSA BANK | G75: Buy | H75: 730000 | I75: EUR | J75: -30192800 | K75: MUR | L75: 41.36 | M75: MR_ON SandT FXMarkets | N75: G44529946 | O75: BO-BO Confirmed | P75: 4140752.3 | Q75: 0 | R75: 4140752.3
A76: 8034234 | B76: FX Fwd | C76: 43881.39 | D76: 44071 | E76: MAURITIUS SUGAR SYNDICATE | F76: MAURITIUS SUGAR SYNDICATE | G76: Buy | H76: 1000000 | I76: EUR | J76: -41250000 | K76: MUR | L76: 41.25 | M76: MR_ON SandT CIB_FX | N76: G01201900 | O76: BO-BO Confirmed | P76: 5706291.1 | Q76: 0 | R76: 5706291.1
A77: 8026628 | B77: FX Fwd | C77: 43880.289 | D77: 44119 | E77: ESQUEL (MAURITIUS) LTD | F77: ESQUEL (MAURITIUS) LTD | G77: Buy | H77: 500000 | I77: USD | J77: -18725000 | K77: MUR | L77: 37.45 | M77: MR_ON SandT CIB_FX | N77: G01201900 | O77: BO-BO Confirmed | P77: 1231750.8 | Q77: 0 | R77: 1231750.8
A78: 8026610 | B78: FX Fwd | C78: 43880.287 | D78: 44141 | E78: ESQUEL (MAURITIUS) LTD | F78: ESQUEL (MAURITIUS) LTD | G78: Buy | H78: 500000 | I78: USD | J78: -18750000 | K78: MUR | L78: 37.5 | M78: MR_ON SandT CIB_FX | N78: G01201900 | O78: BO-BO Confirmed | P78: 1219338.5 | Q78: 0 | R78: 1219338.5
A79: 8021873 | B79: FX Fwd | C79: 43879.276 | D79: 44110 | E79: ESQUEL (MAURITIUS) LTD | F79: ESQUEL (MAURITIUS) LTD | G79: Buy | H79: 500000 | I79: USD | J79: -18675000 | K79: MUR | L79: 37.35 | M79: MR_ON SandT CIB_FX | N79: G01884883 | O79: BO-BO Confirmed | P79: 1276492.7 | Q79: 0 | R79: 1276492.7
A80: 8018285 | B80: FX Fwd | C80: 43878.413 | D80: 44090 | E80: ESQUEL (MAURITIUS) LTD | F80: ESQUEL (MAURITIUS) LTD | G80: Buy | H80: 500000 | I80: USD | J80: -18650000 | K80: MUR | L80: 37.3 | M80: MR_ON SandT CIB_FX | N80: G01884883 | O80: BO-BO Confirmed | P80: 1289708.8 | Q80: 0 | R80: 1289708.8
A81: 7987528 | B81: FX Fwd | C81: 43871.469 | D81: 44211 | E81: BANK ONE | G81: Sell | H81: -895094.88 | I81: EUR | J81: 1000000 | K81: USD | L81: 1.1172 | M81: MR_ON SandT FXMarkets Fwds | N81: G01058632 | O81: BO-BO Confirmed | P81: -2301117.8 | Q81: 0 | R81: -2301117.8
A82: 7987200 | B82: FX Fwd | C82: 43871.444 | D82: 44211 | E82: ABSA BANK | G82: Buy | H82: 895288.01 | I82: EUR | J82: -1000000 | K82: USD | L82: 1.116959 | M82: MR_ON SandT FXMarkets | N82: G01058632 | O82: BO-BO Confirmed | P82: 2310202.9 | Q82: 0 | R82: 2310202.9
A83: 7979734 | B83: FX Fwd | C83: 43868.261 | D83: 44077 | E83: ESQUEL (MAURITIUS) LTD | F83: ESQUEL (MAURITIUS) LTD | G83: Buy | H83: 500000 | I83: USD | J83: -18425000 | K83: MUR | L83: 36.85 | M83: MR_ON SandT CIB_FX | N83: A94100698 | O83: BO-BO Confirmed | P83: 1506601.7 | Q83: 0 | R83: 1506601.7
A84: 7979729 | B84: FX Fwd | C84: 43868.26 | D84: 44090 | E84: ESQUEL (MAURITIUS) LTD | F84: ESQUEL (MAURITIUS) LTD | G84: Buy | H84: 500000 | I84: USD | J84: -18425000 | K84: MUR | L84: 36.85 | M84: MR_ON SandT CIB_FX | N84: A94100698 | O84: BO-BO Confirmed | P84: 1514486.2 | Q84: 0 | R84: 1514486.2
A85: 7925613 | B85: FX Fwd | C85: 43854.229 | D85: 44077 | E85: ESQUEL (MAURITIUS) LTD | F85: ESQUEL (MAURITIUS) LTD | G85: Buy | H85: 1000000 | I85: USD | J85: -36650000 | K85: MUR | L85: 36.65 | M85: MR_ON SandT CIB_FX | N85: A94100698 | O85: BO-BO Confirmed | P85: 3213105.1 | Q85: 0 | R85: 3213105.1
A86: 7906309 | B86: FX Fwd | C86: 43850.451 | D86: 44174 | E86: LAFARGE | F86: LAFARGE | G86: Sell | H86: -400000 | I86: USD | J86: 14732000 | K86: MUR | L86: 36.83 | M86: MR_ON SandT CIB_FX | N86: A94100698 | O86: BO-BO Confirmed | P86: -1258325.2 | Q86: 0 | R86: -1258325.2
A87: 7906297 | B87: FX Fwd | C87: 43850.45 | D87: 44144 | E87: LAFARGE | F87: LAFARGE | G87: Sell | H87: -400000 | I87: USD | J87: 14720000 | K87: MUR | L87: 36.8 | M87: MR_ON SandT CIB_FX | N87: A94100698 | O87: BO-BO Confirmed | P87: -1255968.3 | Q87: 0 | R87: -1255968.3
A88: 7906285 | B88: FX Fwd | C88: 43850.449 | D88: 44113 | E88: LAFARGE | F88: LAFARGE | G88: Sell | H88: -400000 | I88: USD | J88: 14720000 | K88: MUR | L88: 36.8 | M88: MR_ON SandT CIB_FX | N88: A94100698 | O88: BO-BO Confirmed | P88: -1242159.4 | Q88: 0 | R88: -1242159.4
A89: 7906264 | B89: FX Fwd | C89: 43850.448 | D89: 44088 | E89: LAFARGE | F89: LAFARGE | G89: Sell | H89: -700000 | I89: USD | J89: 25760000 | K89: MUR | L89: 36.8 | M89: MR_ON SandT CIB_FX | N89: A94100698 | O89: BO-BO Confirmed | P89: -2153579.5 | Q89: 0 | R89: -2153579.5
A90: 5510100 | B90: FX Fwd | C90: 43266.228 | D90: 44357 | E90: BH PROPERTY INVESTMENTS LTD | F90: BH PROPERTY INVESTMENTS LTD | G90: Sell | H90: -22246.94 | I90: EUR | J90: 1000000 | K90: MUR | L90: 44.95 | M90: MR_ON SandT CIB_FX | N90: G01049329 | O90: BO-BO Confirmed | P90: -62155.363 | Q90: 0 | R90: -62155.363
A91: 5507458 | B91: FX Fwd | C91: 43265.447 | D91: 45089 | E91: BH PROPERTY INVESTMENTS LTD | F91: BH PROPERTY INVESTMENTS LTD | G91: Sell | H91: -22246.94 | I91: EUR | J91: 1000000 | K91: MUR | L91: 44.95 | M91: MR_ON SandT CIB_FX | N91: G01049329 | O91: BO-BO Confirmed | P91: -133392.94 | Q91: 0 | R91: -133392.94
A92: 5507425 | B92: FX Fwd | C92: 43265.445 | D92: 45056 | E92: BH PROPERTY INVESTMENTS LTD | F92: BH PROPERTY INVESTMENTS LTD | G92: Sell | H92: -22246.94 | I92: EUR | J92: 1000000 | K92: MUR | L92: 44.95 | M92: MR_ON SandT CIB_FX | N92: G01049329 | O92: BO-BO Confirmed | P92: -129750.49 | Q92: 0 | R92: -129750.49
...

Sheet pivot FX DEALS OUT
B1: PIVOT BY CCY 1 | E1: PIVOT BY CCY 1 | I1: PIVOT FOR BOTH CC1 & CCY2 | L1: PIVOT FOR BOTH CC1 & CCY2
B3: Row Labels | C3: Sum of CCY 1 Amount | E3: Row Labels | F3: Sum of CCY 1 Amount | I3: Row Labels | J3: Sum of Sum of CCY 1 Amount | L3: Row Labels | M3: Sum of Sum of CCY 1 Amount
B4: AUD | C4: 8000 | E4: AUD | F4: 8000 | I4: (blank) | L4: (blank)
B5: EUR | C5: -25853666 | E5: EUR | F5: -25853666 | I5: AUD | J5: 8000 | L5: AUD | M5: 8000
B6: GBP | C6: 9910142.9 | E6: GBP | F6: 9910142.9 | I6: EUR | J6: -25853666 | L6: EUR | M6: -25853666
B7: JPY | C7: -77060301 | E7: JPY | F7: -77060301 | I7: GBP | J7: 9910142.9 | L7: GBP | M7: 9910142.9
B8: SGD | C8: -141864.75 | E8: SGD | F8: -141864.75 | I8: Grand Total | J8: 3.1918332e+08 | L8: Grand Total | M8: 3.1918332e+08
B9: USD | C9: -19692880 | E9: USD | F9: -19692880 | I9: JPY | J9: -73940301 | L9: JPY | M9: -73940301
B10: ZAR | C10: -1169024.2 | E10: ZAR | F10: -1169024.2 | I10: MUR | J10: 4.0274286e+08 | L10: MUR | M10: 4.0274286e+08
B11: (blank) | E11: (blank) | I11: Row Labels | J11: 0 | L11: Row Labels | M11: 0
B12: CHF | C12: -145747 | E12: CHF | F12: -145747 | I12: USD | J12: 10427750 | L12: USD | M12: 10427750
B13: Grand Total | C13: -1.1414534e+08 | E13: Grand Total | F13: -1.1414534e+08 | I13: ZAR | J13: -289854.18 | L13: ZAR | M13: -289854.18
I14: (blank) | L14: (blank)
I15: CHF | J15: -10747 | L15: CHF | M15: -10747
I16: CNH | J16: -2000000 | L16: CNH | M16: -2000000
I17: SEK | J17: -60000 | L17: SEK | M17: -60000
I18: HKD | J18: -987000 | L18: HKD | M18: -987000
I19: AED | J19: -1000000 | L19: AED | M19: -1000000
I20: SGD | J20: 8135.25 | L20: SGD | M20: 8135.25
B21: PIVOT BY CCY 2 | E21: PIVOT BY CCY 2 | I21: CAD | J21: 20000 | L21: CAD | M21: 20000
I22: SCR | J22: 208000 | L22: SCR | M22: 208000
B23: Row Labels | C23: Sum of CCY 2 Amount | E23: Row Labels | F23: Sum of CCY 2 Amount | I23: PIVOT BY CCY 2 | L23: PIVOT BY CCY 2
B24: HKD | C24: -987000 | E24: HKD | F24: -987000 | I24: Grand Total | J24: 6.3836663e+08 | L24: Grand Total | M24: 6.3836663e+08
B25: CAD | C25: 20000 | E25: CAD | F25: 20000
B26: CNH | C26: -2000000 | E26: CNH | F26: -2000000
B27: SEK | C27: -60000 | E27: SEK | F27: -60000
B28: SCR | C28: 208000 | E28: SCR | F28: 208000
B29: JPY | C29: 3120000 | E29: JPY | F29: 3120000
B30: MUR | C30: 4.0274286e+08 | E30: MUR | F30: 4.0274286e+08
B31: USD | C31: 30120630 | E31: USD | F31: 30120630
B32: ZAR | C32: 879170 | E32: ZAR | F32: 879170
B33: (blank) | E33: (blank)
B34: CHF | C34: 135000 | E34: CHF | F34: 135000
B35: SGD | C35: 150000 | E35: SGD | F35: 150000
B36: AED | C36: -1000000 | E36: AED | F36: -1000000
B37: Grand Total | C37: 4.3332866e+08 | E37: Grand Total | F37: 4.3332866e+08

Sheet FA LIVE
A1: IDKEY | B1: CUR | C1: SysID | D1: Deal Date | E1: Value Day | F1: CounterParty | G1: Price | H1: Nominal | I1: Ageing1 | J1: Ageing2 | K1: Customer | L1: Relationship Manager | M1: Comment
A2: AED878996814/08/202024/08/2020ABSA BANK3.672791000000 | B2: AED | C2: 8789968 | D2: 44057 | E2: 44067 | F2: ABSA BANK | G2: 3.67279 | H2: 1000000 | I2: 0 | J2: Less than 90 days
A3: AED881609121/08/202014/09/2020ABSA BANK3.673091000000 | B3: AED | C3: 8816091 | D3: 44064 | E3: 44088 | F3: ABSA BANK | G3: 3.67309 | H3: 1000000 | I3: 0 | J3: Less than 90 days
A4: AED881609021/08/202024/08/2020ABSA BANK3.6727-1000000 | B4: AED | C4: 8816090 | D4: 44064 | E4: 44067 | F4: ABSA BANK | G4: 3.6727 | H4: -1000000 | I4: 0 | J4: Less than 90 days
A5: AUD881128620/08/202024/08/2020BARCLAYS BANK PLC LONDON0.71596-6000 | B5: AUD | C5: 8811286 | D5: 44063 | E5: 44067 | F5: BARCLAYS BANK PLC LONDON | G5: 0.71596 | H5: -6000 | I5: 0 | J5: Less than 90 days
A6: AUD881111120/08/202024/08/2020BARCLAYS BANK PLC LONDON0.71608-2000 | B6: AUD | C6: 8811111 | D6: 44063 | E6: 44067 | F6: BARCLAYS BANK PLC LONDON | G6: 0.71608 | H6: -2000 | I6: 0 | J6: Less than 90 days
A7: CAD881502721/08/202024/08/2020BARCLAYS BANK PLC LONDON1.3192-40000 | B7: CAD | C7: 8815027 | D7: 44064 | E7: 44067 | F7: BARCLAYS BANK PLC LONDON | G7: 1.3192 | H7: -40000 | I7: 0 | J7: Less than 90 days
A8: CAD881502621/08/202024/08/2020BARCLAYS BANK PLC LONDON1.3193920000 | B8: CAD | C8: 8815026 | D8: 44064 | E8: 44067 | F8: BARCLAYS BANK PLC LONDON | G8: 1.31939 | H8: 20000 | I8: 0 | J8: Less than 90 days
A9: CHF881632921/08/202025/08/2020BARCLAYS BANK PLC LONDON0.91356-135000 | B9: CHF | C9: 8816329 | D9: 44064 | E9: 44068 | F9: BARCLAYS BANK PLC LONDON | G9: 0.91356 | H9: -135000 | I9: 0 | J9: Less than 90 days
A10: CHF881544121/08/202024/08/2020SOCIMED LTD44.15145747 | B10: CHF | C10: 8815441 | D10: 44064 | E10: 44067 | F10: SOCIMED LTD | G10: 44.15 | H10: 145747 | I10: 0 | J10: Less than 90 days | K10: SOCIMED LTD | L10: Georgy Geerdharry
A11: CNH876191110/08/202025/08/2020BARCLAYS BANK PLC LONDON6.977972000000 | B11: CNH | C11: 8761911 | D11: 44053 | E11: 44068 | F11: BARCLAYS BANK PLC LONDON | G11: 6.97797 | H11: 2000000 | I11: 0 | J11: Less than 90 days
A12: EUR869705524/07/202029/01/2021NUMELEC LTD47.5610000 | B12: EUR | C12: 8697055 | D12: 44036 | E12: 44225 | F12: NUMELEC LTD | G12: 47.56 | H12: 10000 | I12: 0 | J12: Less than 90 days | K12: NUMELEC LTD | L12: Rodolphe Couronne
A13: EUR875560407/08/202007/12/2020MRC WIRE PRODUCTS LTD47.5530000 | B13: EUR | C13: 8755604 | D13: 44050 | E13: 44172 | F13: MRC WIRE PRODUCTS LTD | G13: 47.55 | H13: 30000 | I13: 0 | J13: Less than 90 days | K13: MRC WIRE PRODUCTS LTD | L13: Christine John Chuan
A14: EUR864260113/07/202020/11/2020MAURITIUS SUGAR SYNDICATE46-500000 | B14: EUR | C14: 8642601 | D14: 44025 | E14: 44155 | F14: MAURITIUS SUGAR SYNDICATE | G14: 46 | H14: -500000 | I14: 0 | J14: Less than 90 days | K14: MAURITIUS SUGAR SYNDICATE | L14: C Yue Chi Ming
A15: EUR874810506/08/202020/10/2020PANAGORA MARKETING CO LTD47.95182 | B15: EUR | C15: 8748105 | D15: 44049 | E15: 44124 | F15: PANAGORA MARKETING CO LTD | G15: 47.9 | H15: 5182 | I15: 0 | J15: Less than 90 days | K15: PANAGORA MARKETING CO LTD | L15: Kavita Ramruttun
A16: EUR868411222/07/202029/10/2020MAURITIUS SUGAR SYNDICATE46.75-500000 | B16: EUR | C16: 8684112 | D16: 44034 | E16: 44133 | F16: MAURITIUS SUGAR SYNDICATE | G16: 46.75 | H16: -500000 | I16: 0 | J16: Less than 90 days | K16: MAURITIUS SUGAR SYNDICATE | L16: C Yue Chi Ming
A17: EUR881343921/08/202025/08/2020BARCLAYS BANK PLC LONDON1.18708100000 | B17: EUR | C17: 8813439 | D17: 44064 | E17: 44068 | F17: BARCLAYS BANK PLC LONDON | G17: 1.18708 | H17: 100000 | I17: 0 | J17: Less than 90 days
A18: EUR870252127/07/202010/12/2020MAURITIUS SUGAR SYNDICATE47.6-500000 | B18: EUR | C18: 8702521 | D18: 44039 | E18: 44175 | F18: MAURITIUS SUGAR SYNDICATE | G18: 47.6 | H18: -500000 | I18: 0 | J18: Less than 90 days | K18: MAURITIUS SUGAR SYNDICATE | L18: C Yue Chi Ming
A19: EUR881330521/08/202025/08/2020SHIBANI FINANCE COMPANY LIMITED47.12-100000 | B19: EUR | C19: 8813305 | D19: 44064 | E19: 44068 | F19: SHIBANI FINANCE COMPANY LIMITED | G19: 47.12 | H19: -100000 | I19: 0 | J19: Less than 90 days | K19: SHIBANI FINANCE COMPANY LIMITED | L19: Georgy Geerdharry
A20: EUR872694031/07/202015/09/2020MSJ LTD47.9108619 | B20: EUR | C20: 8726940 | D20: 44043 | E20: 44089 | F20: MSJ LTD | G20: 47.9 | H20: 108619 | I20: 0 | J20: Less than 90 days | K20: MSJ LTD | L20: Kavita Ramruttun
A21: EUR869654624/07/202015/10/2020MRC WIRE PRODUCTS LTD47.485000 | B21: EUR | C21: 8696546 | D21: 44036 | E21: 44119 | F21: MRC WIRE PRODUCTS LTD | G21: 47.4 | H21: 85000 | I21: 0 | J21: Less than 90 days | K21: MRC WIRE PRODUCTS LTD | L21: Christine John Chuan
A22: EUR869624124/07/202026/10/2020CFAO MOTORS MAURITIUS LTD47.5500000 | B22: EUR | C22: 8696241 | D22: 44036 | E22: 44130 | F22: CFAO MOTORS MAURITIUS LTD | G22: 47.5 | H22: 500000 | I22: 0 | J22: Less than 90 days
A23: EUR872090030/07/202015/12/2020MAURITIUS SUGAR SYNDICATE47.6-500000 | B23: EUR | C23: 8720900 | D23: 44042 | E23: 44180 | F23: MAURITIUS SUGAR SYNDICATE | G23: 47.6 | H23: -500000 | I23: 0 | J23: Less than 90 days | K23: MAURITIUS SUGAR SYNDICATE | L23: C Yue Chi Ming
A24: EUR870813928/07/202004/09/2020MAURITIUS SUGAR SYNDICATE1.174-500000 | B24: EUR | C24: 8708139 | D24: 44040 | E24: 44078 | F24: MAURITIUS SUGAR SYNDICATE | G24: 1.174 | H24: -500000 | I24: 0 | J24: Less than 90 days | K24: MAURITIUS SUGAR SYNDICATE | L24: C Yue Chi Ming
A25: EUR874020005/08/202010/09/2020CFAO MOTORS MAURITIUS LTD47.39191579.43 | B25: EUR | C25: 8740200 | D25: 44048 | E25: 44084 | F25: CFAO MOTORS MAURITIUS LTD | G25: 47.39 | H25: 191579.43 | I25: 0 | J25: Less than 90 days
A26: EUR550722914/06/201811/04/2022BH PROPERTY INVESTMENTS LTD44.9522246.94 | B26: EUR | C26: 5507229 | D26: 43265 | E26: 44662 | F26: BH PROPERTY INVESTMENTS LTD | G26: 44.95 | H26: 22246.94 | I26: 0 | J26: Less than 90 days
A27: EUR881376121/08/202025/08/2020Mauritius IBD1.1845-2000000 | B27: EUR | C27: 8813761 | D27: 44064 | E27: 44068 | F27: Mauritius IBD | G27: 1.1845 | H27: -2000000 | I27: 0 | J27: Less than 90 days
A28: EUR881375321/08/202025/08/2020Mauritius IBD1.184192000000 | B28: EUR | C28: 8813753 | D28: 44064 | E28: 44068 | F28: Mauritius IBD | G28: 1.18419 | H28: 2000000 | I28: 0 | J28: Less than 90 days
A29: EUR881374321/08/202025/08/2020CITIBANK N.A. LONDON1.18452000000 | B29: EUR | C29: 8813743 | D29: 44064 | E29: 44068 | F29: CITIBANK N.A. LONDON | G29: 1.1845 | H29: 2000000 | I29: 0 | J29: Less than 90 days
A30: EUR881354821/08/202024/08/2020IRELAND BLYTH LIMITED1.1876400000 | B30: EUR | C30: 8813548 | D30: 44064 | E30: 44067 | F30: IRELAND BLYTH LIMITED | G30: 1.1876 | H30: 400000 | I30: 0 | J30: Less than 90 days | K30: IRELAND BLYTH LIMITED | L30: Kavita Ramruttun
A31: EUR881370121/08/202025/08/2020Mauritius IBD1.18731000000 | B31: EUR | C31: 8813701 | D31: 44064 | E31: 44068 | F31: Mauritius IBD | G31: 1.1873 | H31: 1000000 | I31: 0 | J31: Less than 90 days
A32: EUR881357921/08/202025/08/2020ABSA BANK1.1873-1000000 | B32: EUR | C32: 8813579 | D32: 44064 | E32: 44068 | F32: ABSA BANK | G32: 1.1873 | H32: -1000000 | I32: 0 | J32: Less than 90 days
A33: EUR881373521/08/202025/08/2020CITIBANK N.A. LONDON1.18419-2000000 | B33: EUR | C33: 8813735 | D33: 44064 | E33: 44068 | F33: CITIBANK N.A. LONDON | G33: 1.18419 | H33: -2000000 | I33: 0 | J33: Less than 90 days
A34: EUR550650914/06/201812/04/2021BH PROPERTY INVESTMENTS LTD44.9522246.94 | B34: EUR | C34: 5506509 | D34: 43265 | E34: 44298 | F34: BH PROPERTY INVESTMENTS LTD | G34: 44.95 | H34: 22246.94 | I34: 0 | J34: Less than 90 days
A35: EUR860146502/07/202031/08/2020H.VAULBERT DE CHANTILLY LTD(HVC LTD)45.5875000 | B35: EUR | C35: 8601465 | D35: 44014 | E35: 44074 | F35: H.VAULBERT DE CHANTILLY LTD(HVC LTD) | G35: 45.58 | H35: 75000 | I35: 0 | J35: Less than 90 days
A36: EUR550726614/06/201810/06/2022BH PROPERTY INVESTMENTS LTD44.9522246.94 | B36: EUR | C36: 5507266 | D36: 43265 | E36: 44722 | F36: BH PROPERTY INVESTMENTS LTD | G36: 44.95 | H36: 22246.94 | I36: 0 | J36: Less than 90 days
A37: EUR550724514/06/201810/05/2022BH PROPERTY INVESTMENTS LTD44.9522246.94 | B37: EUR | C37: 5507245 | D37: 43265 | E37: 44691 | F37: BH PROPERTY INVESTMENTS LTD | G37: 44.95 | H37: 22246.94 | I37: 0 | J37: Less than 90 days
A38: EUR551010015/06/201810/06/2021BH PROPERTY INVESTMENTS LTD44.9522246.94 | B38: EUR | C38: 5510100 | D38: 43266 | E38: 44357 | F38: BH PROPERTY INVESTMENTS LTD | G38: 44.95 | H38: 22246.94 | I38: 0 | J38: Less than 90 days
A39: EUR550630314/06/201810/09/2020BH PROPERTY INVESTMENTS LTD44.9522246.94 | B39: EUR | C39: 5506303 | D39: 43265 | E39: 44084 | F39: BH PROPERTY INVESTMENTS LTD | G39: 44.95 | H39: 22246.94 | I39: 0 | J39: Less than 90 days
A40: EUR550630914/06/201813/10/2020BH PROPERTY INVESTMENTS LTD44.9522246.94 | B40: EUR | C40: 5506309 | D40: 43265 | E40: 44117 | F40: BH PROPERTY INVESTMENTS LTD | G40: 44.95 | H40: 22246.94 | I40: 0 | J40: Less than 90 days
...

Sheet PIVOT FA LIVE
B3: Row Labels | C3: Sum of Nominal | E3: Row Labels | F3: Sum of Nominal
B4: AUD | C4: -8000 | E4: AUD | F4: -8000
B5: CAD | C5: -20000 | E5: CAD | F5: -20000
B6: EUR | C6: 25853666 | E6: EUR | F6: 25853666
B7: GBP | C7: -9910142.9 | E7: GBP | F7: -9910142.9
B8: HKD | C8: 987000 | E8: HKD | F8: 987000
B9: JPY | C9: 73940301 | E9: JPY | F9: 73940301
B10: SGD | C10: -8135.25 | E10: SGD | F10: -8135.25
B11: USD | C11: -10427750 | E11: USD | F11: -10427750
B12: ZAR | C12: 289854.18 | E12: ZAR | F12: 289854.18
B13: (blank) | E13: (blank)
B14: CHF | C14: 10747 | E14: CHF | F14: 10747
B15: AED | C15: 1000000 | E15: AED | F15: 1000000
B16: CNH | C16: 2000000 | E16: CNH | F16: 2000000
B17: SCR | C17: -208000 | E17: SCR | F17: -208000
B18: SEK | C18: 60000 | E18: SEK | F18: 60000
B19: Grand Total | C19: 83559539 | E19: Grand Total | F19: 83559539

Sheet COMPARISON
A2: Currency | B2: Live FX Deals on Access | C2: Live FX Deals on FA | D2: Diff | E2: Comments
A3: AUD | B3: =VLOOKUP(A3,'PIVOT FA LIVE'!E:F,2,0) -> -8000 | C3: =VLOOKUP(A3,'pivot FX DEALS OUT'!L:M,2,0) -> 8000 | D3: =B3+C3 -> 0
A4: AED | B4: =VLOOKUP(A4,'PIVOT FA LIVE'!E:F,2,0) -> 1000000 | C4: =VLOOKUP(A4,'pivot FX DEALS OUT'!L:M,2,0) -> -1000000 | D4: =B4+C4 -> 0
A5: BHD | B5: =VLOOKUP(A5,'PIVOT FA LIVE'!E:F,2,0) -> #N/A | C5: =VLOOKUP(A5,'pivot FX DEALS OUT'!L:M,2,0) -> #N/A | D5: =B5+C5 -> #N/A
A6: BWP | B6: =VLOOKUP(A6,'PIVOT FA LIVE'!E:F,2,0) -> #N/A | C6: =VLOOKUP(A6,'pivot FX DEALS OUT'!L:M,2,0) -> #N/A | D6: =B6+C6 -> #N/A
A7: CAD | B7: =VLOOKUP(A7,'PIVOT FA LIVE'!E:F,2,0) -> -20000 | C7: =VLOOKUP(A7,'pivot FX DEALS OUT'!L:M,2,0) -> 20000 | D7: =B7+C7 -> 0
A8: CHF | B8: =VLOOKUP(A8,'PIVOT FA LIVE'!E:F,2,0) -> 10747 | C8: =VLOOKUP(A8,'pivot FX DEALS OUT'!L:M,2,0) -> -10747 | D8: =B8+C8 -> 0
A9: CNH | B9: =VLOOKUP(A9,'PIVOT FA LIVE'!E:F,2,0) -> 2000000 | C9: =VLOOKUP(A9,'pivot FX DEALS OUT'!L:M,2,0) -> -2000000 | D9: =B9+C9 -> 0
A10: DKK | B10: =VLOOKUP(A10,'PIVOT FA LIVE'!E:F,2,0) -> #N/A | C10: =VLOOKUP(A10,'pivot FX DEALS OUT'!L:M,2,0) -> #N/A | D10: =B10+C10 -> #N/A
A11: EUR | B11: =VLOOKUP(A11,'PIVOT FA LIVE'!E:F,2,0) -> 25853666 | C11: =VLOOKUP(A11,'pivot FX DEALS OUT'!L:M,2,0) -> -25853666 | D11: =B11+C11 -> 0
A12: GBP | B12: =VLOOKUP(A12,'PIVOT FA LIVE'!E:F,2,0) -> -9910142.9 | C12: =VLOOKUP(A12,'pivot FX DEALS OUT'!L:M,2,0) -> 9910142.9 | D12: =B12+C12 -> 0
A13: GHS | B13: =VLOOKUP(A13,'PIVOT FA LIVE'!E:F,2,0) -> #N/A | C13: =VLOOKUP(A13,'pivot FX DEALS OUT'!L:M,2,0) -> #N/A | D13: =B13+C13 -> #N/A
A14: HKD | B14: =VLOOKUP(A14,'PIVOT FA LIVE'!E:F,2,0) -> 987000 | C14: =VLOOKUP(A14,'pivot FX DEALS OUT'!L:M,2,0) -> -987000 | D14: =B14+C14 -> 0
... A32: ZMW | B32: =VLOOKUP(A32,'PIVOT FA LIVE'!E:F,2,0) -> #N/A | C32: =VLOOKUP(A32,'pivot FX DEALS OUT'!L:M,2,0) -> #N/A | D32: =B32+C32 -> #N/A

Sheet CURR FX DEALS OUT
A1: trade | B1: Trade Type | C1: Deal Date | D1: Value Date | E1: Counterparty | F1: External Counterparty | G1: Direction | H1: CCY 1 Amount | I1: CCY 1 | J1: CCY 2 Amount | K1: CCY 2 | L1: Exchange Rate | M1: Book | N1: Dealer | O1: Status | P1: TPL | Q1: Cash | R1: Val | T1: XX
T2: =VLOOKUP(A2,'CURR FA LIVE'!$A:$A,1,0) -> #N/A
T3: =VLOOKUP(A3,'CURR FA LIVE'!$A:$A,1,0) -> #N/A
T4: =VLOOKUP(A4,'CURR FA LIVE'!$A:$A,1,0) -> #N/A
T5: =VLOOKUP(A5,'CURR FA LIVE'!$A:$A,1,0) -> #N/A
T6: =VLOOKUP(A6,'CURR FA LIVE'!$A:$A,1,0) -> #N/A
T7: =VLOOKUP(A7,'CURR FA LIVE'!$A:$A,1,0) -> #N/A
T8: =VLOOKUP(A8,'CURR FA LIVE'!$A:$A,1,0) -> #N/A
T9: =VLOOKUP(A9,'CURR FA LIVE'!$A:$A,1,0) -> #N/A
T10: =VLOOKUP(A10,'CURR FA LIVE'!$A:$A,1,0) -> #N/A
T11: =VLOOKUP(A11,'CURR FA LIVE'!$A:$A,1,0) -> #N/A
T12: =VLOOKUP(A12,'CURR FA LIVE'!$A:$A,1,0) -> #N/A
T13: =VLOOKUP(A13,'CURR FA LIVE'!$A:$A,1,0) -> #N/A
... T229: =VLOOKUP(A229,'CURR FA LIVE'!$A:$A,1,0) -> #N/A

Sheet CURR FA LIVE
A1: SysID

Sheet SUMMARY
A2: Currency | B2: Live FX Deals on Access | C2: Live FX Deals on FA | D2: Diff
A3: AUD | B3: =IFERROR(COMPARISON!B3,0) -> -8000 | C3: =IFERROR(COMPARISON!C3,0) -> 8000 | D3: =B3+C3 -> 0
A4: AED | B4: =IFERROR(COMPARISON!B4,0) -> 1000000 | C4: =IFERROR(COMPARISON!C4,0) -> -1000000 | D4: =B4+C4 -> 0
A5: BHD | B5: =IFERROR(COMPARISON!B5,0) -> 0 | C5: =IFERROR(COMPARISON!C5,0) -> 0 | D5: =B5+C5 -> 0
A6: BWP | B6: =IFERROR(COMPARISON!B6,0) -> 0 | C6: =IFERROR(COMPARISON!C6,0) -> 0 | D6: =B6+C6 -> 0
A7: CAD | B7: =IFERROR(COMPARISON!B7,0) -> -20000 | C7: =IFERROR(COMPARISON!C7,0) -> 20000 | D7: =B7+C7 -> 0
A8: CHF | B8: =IFERROR(COMPARISON!B8,0) -> 10747 | C8: =IFERROR(COMPARISON!C8,0) -> -10747 | D8: =B8+C8 -> 0
A9: CNH | B9: =IFERROR(COMPARISON!B9,0) -> 2000000 | C9: =IFERROR(COMPARISON!C9,0) -> -2000000 | D9: =B9+C9 -> 0
A10: DKK | B10: =IFERROR(COMPARISON!B10,0) -> 0 | C10: =IFERROR(COMPARISON!C10,0) -> 0 | D10: =B10+C10 -> 0
A11: EUR | B11: =IFERROR(COMPARISON!B11,0) -> 25853666 | C11: =IFERROR(COMPARISON!C11,0) -> -25853666 | D11: =B11+C11 -> 0
A12: GBP | B12: =IFERROR(COMPARISON!B12,0) -> -9910142.9 | C12: =IFERROR(COMPARISON!C12,0) -> 9910142.9 | D12: =B12+C12 -> 0
A13: GHS | B13: =IFERROR(COMPARISON!B13,0) -> 0 | C13: =IFERROR(COMPARISON!C13,0) -> 0 | D13: =B13+C13 -> 0
A14: HKD | B14: =IFERROR(COMPARISON!B14,0) -> 987000 | C14: =IFERROR(COMPARISON!C14,0) -> -987000 | D14: =B14+C14 -> 0
... A32: ZMW | B32: =IFERROR(COMPARISON!B32,0) -> 0 | C32: =IFERROR(COMPARISON!C32,0) -> 0 | D32: =B32+C32 -> 0
A34: EARLY SETTLEMENT | H34: =F141 -> 0 | I34: Net PnL | J34: =E141-SUM(D3:D31) -> 4.6566129e-10
A35: Deal | B35: Name | C35: Value date | F35: PnL
B36: =VLOOKUP(A36,'fx deals outs reworked'!$A$2:$R$889,5,0) -> #N/A | C36: =VLOOKUP(A36,'fx deals outs reworked'!$A$2:$R$889,4,0) -> #N/A | F36: =IFERROR(VLOOKUP(A36,'fx deals outs reworked'!$A$2:$R$889,16,0),0) -> 0
B37: =VLOOKUP(A37,'fx deals outs reworked'!$A$2:$R$889,5,0) -> #N/A | C37: =VLOOKUP(A37,'fx deals outs reworked'!$A$2:$R$889,4,0) -> #N/A | F37: =IFERROR(VLOOKUP(A37,'fx deals outs reworked'!$A$2:$R$889,16,0),0) -> 0
B38: =VLOOKUP(A38,'fx deals outs reworked'!$A$2:$R$889,5,0) -> #N/A | C38: =VLOOKUP(A38,'fx deals outs reworked'!$A$2:$R$889,4,0) -> #N/A | F38: =IFERROR(VLOOKUP(A38,'fx deals outs reworked'!$A$2:$R$889,16,0),0) -> 0
B39: =VLOOKUP(A39,'fx deals outs reworked'!$A$2:$R$889,5,0) -> #N/A | C39: =VLOOKUP(A39,'fx deals outs reworked'!$A$2:$R$889,4,0) -> #N/A | F39: =IFERROR(VLOOKUP(A39,'fx deals outs reworked'!$A$2:$R$889,16,0),0) -> 0
B40: =VLOOKUP(A40,'fx deals outs reworked'!$A$2:$R$889,5,0) -> #N/A | C40: =VLOOKUP(A40,'fx deals outs reworked'!$A$2:$R$889,4,0) -> #N/A | F40: =IFERROR(VLOOKUP(A40,'fx deals outs reworked'!$A$2:$R$889,16,0),0) -> 0
B41: =VLOOKUP(A41,'fx deals outs reworked'!$A$2:$R$889,5,0) -> #N/A | C41: =VLOOKUP(A41,'fx deals outs reworked'!$A$2:$R$889,4,0) -> #N/A | F41: =IFERROR(VLOOKUP(A41,'fx deals outs reworked'!$A$2:$R$889,16,0),0) -> 0
B42: =VLOOKUP(A42,'fx deals outs reworked'!$A$2:$R$889,5,0) -> #N/A | C42: =VLOOKUP(A42,'fx deals outs reworked'!$A$2:$R$889,4,0) -> #N/A | F42: =IFERROR(VLOOKUP(A42,'fx deals outs reworked'!$A$2:$R$889,16,0),0) -> 0
B43: =VLOOKUP(A43,'fx deals outs reworked'!$A$2:$R$889,5,0) -> #N/A | C43: =VLOOKUP(A43,'fx deals outs reworked'!$A$2:$R$889,4,0) -> #N/A | F43: =IFERROR(VLOOKUP(A43,'fx deals outs reworked'!$A$2:$R$889,16,0),0) -> 0
B44: =VLOOKUP(A44,'fx deals outs reworked'!$A$2:$R$889,5,0) -> #N/A | C44: =VLOOKUP(A44,'fx deals outs reworked'!$A$2:$R$889,4,0) -> #N/A | F44: =IFERROR(VLOOKUP(A44,'fx deals outs reworked'!$A$2:$R$889,16,0),0) -> 0
B45: =VLOOKUP(A45,'fx deals outs reworked'!$A$2:$R$889,5,0) -> #N/A | C45: =VLOOKUP(A45,'fx deals outs reworked'!$A$2:$R$889,4,0) -> #N/A | F45: =IFERROR(VLOOKUP(A45,'fx deals outs reworked'!$A$2:$R$889,16,0),0) -> 0
B46: =VLOOKUP(A46,'fx deals outs reworked'!$A$2:$R$889,5,0) -> #N/A | C46: =VLOOKUP(A46,'fx deals outs reworked'!$A$2:$R$889,4,0) -> #N/A | F46: =IFERROR(VLOOKUP(A46,'fx deals outs reworked'!$A$2:$R$889,16,0),0) -> 0
B47: =VLOOKUP(A47,'fx deals outs reworked'!$A$2:$R$889,5,0) -> #N/A | C47: =VLOOKUP(A47,'fx deals outs reworked'!$A$2:$R$889,4,0) -> #N/A | F47: =IFERROR(VLOOKUP(A47,'fx deals outs reworked'!$A$2:$R$889,16,0),0) -> 0
... B140: =VLOOKUP(A140,'fx deals outs reworked'!$A$2:$R$889,5,0) -> #N/A | C140: =VLOOKUP(A140,'fx deals outs reworked'!$A$2:$R$889,4,0) -> #N/A | F140: =IFERROR(VLOOKUP(A140,'fx deals outs reworked'!$A$2:$R$889,16,0),0) -> 0
E141: =SUM(E36:E140) -> 0 | F141: =SUM(F36:F140) -> 0

Sheet Sheet1

Sheet Sheet2
